<mujoco model="fingerpro">
  <compiler angle="degree" coordinate="local" inertiafromgeom="true"/>
  <option timestep="0.01" gravity="0 0 -9.81" iterations="100" />
  <custom>
    <!-- brax custom params -->
    <numeric data="0.0 0.0 0.0" name="init_qpos"/>
    <!-- <numeric data="0.0" name="init_qpos"/> -->
    <numeric data="1" name="constraint_limit_stiffness"/>
    <numeric data="4" name="constraint_stiffness"/>
    <numeric data="1" name="constraint_ang_damping"/>
    <numeric data="1" name="constraint_vel_damping"/>
    <numeric data="1" name="joint_scale_pos"/>
    <numeric data="1" name="joint_scale_ang"/>
    <numeric data="0.0" name="ang_damping"/>
    <numeric data="1" name="spring_mass_scale"/>
    <numeric data="1" name="spring_inertia_scale"/>
    <numeric data="15" name="solver_maxls"/>
  </custom>
  <default>
    <joint armature="0" damping="1" limited="true"/>
    <geom contype="0" conaffinity="0" condim="3" density="1.0" friction="1 1 1"/>
  </default>
  <asset>
    <texture builtin="gradient" height="100" rgb1="1 1 1" rgb2="0 0 0" type="skybox" width="100"/>
    <texture builtin="flat" height="1278" mark="cross" markrgb="1 1 1" name="texgeom" random="0.01" rgb1="0.8 0.6 0.4" rgb2="0.8 0.6 0.4" type="cube" width="127"/>
    <texture builtin="checker" height="100" name="texplane" rgb1="0 0 0" rgb2="0.8 0.8 0.8" type="2d" width="100"/>
    <material name="MatPlane" reflectance="0.5" shininess="1" specular="1" texrepeat="60 60" texture="texplane"/>
    <material name="geom" texture="texgeom" texuniform="true"/>
    <mesh name="finger_upper_link" file="assets/pro/prox-sim.stl"/>
    <mesh name="finger_middle_link" file="assets/pro/int_sim.stl"/>
    <mesh name="finger_lower_link" file="assets/pro/tip_link_sim.stl"/>
    <mesh name="finger_tip_link" file="assets/pro/tip_sim.stl"/>
  </asset>
  <worldbody>
    <light cutoff="100" diffuse="1 1 1" dir="-0 0 -1.3" directional="true" exponent="1" pos="0 0 1.3" specular=".1 .1 .1"/>
    <geom conaffinity="1" condim="3" material="MatPlane" name="floor" pos="0 0 0" size="40 40 40" type="plane"/>
    <body name="finger_upper_link" pos="0.02 0 0.75">
      <joint axis="0 1 0" name="ankle_1" pos="0.0 0.0 0.0" range="-19 57.5" type="hinge"/>
      <camera name="track" mode="trackcom" pos="0 -3 0.3" xyaxes="1 0 0 0 0 1"/>
      <geom name="finger_upper_link" pos="0 0 0" mass="0.26689" type="mesh" mesh="finger_upper_link"/>
      <body name="finger_middle_link" pos="0.015 0.05 0">
        <geom name="finger_middle_link" contype="1" type="mesh" mesh="finger_middle_link" mass="0.27163"/>
        <joint axis="1 0 0" name="ankle_2" pos="0.0 0.0 0.0" range="0 90" type="hinge"/>
        <body name="finger_lower_link" pos="0.05 0 -0.16">
          <joint axis="1 0 0" name="ankle_3" pos="0.0 0.0 0.0" range="-155 0" type="hinge"/>
          <geom name="finger_lower_link" contype="1" type="mesh" mesh="finger_lower_link" mass="0.05569"/>
          <body name="finger_tip_link" pos="0.018 0 -0.16">
            <geom name="finger_tip_link" contype="1" type="mesh" mesh="finger_tip_link" mass="0.0092"/>
          </body>
        </body>
      </body>
    </body>
  </worldbody>
  <actuator>
    <motor ctrllimited="true" ctrlrange="-1.0 1.0" joint="ankle_1" gear="1"/> 
    <motor ctrllimited="true" ctrlrange="-1.0 1.0" joint="ankle_2" gear="1"/>
    <motor ctrllimited="true" ctrlrange="-1.0 1.0" joint="ankle_3" gear="1"/>
  </actuator>
</mujoco>
